<robot xmlns:sensor="http://playerstage.sourceforge.net/gazebo/xmlschema/#sensor"
       xmlns:controller="http://playerstage.sourceforge.net/gazebo/xmlschema/#controller"
       xmlns:interface="http://playerstage.sourceforge.net/gazebo/xmlschema/#interface"
       xmlns:xacro="http://ros.org/wiki/xacro"
	   name="pan_tilt_thermapp_camera"
	>
	
	<xacro:arg name="camera_name" default="cam"/>
	<property name="camera_name" value="$(arg camera_name)" />
	<xacro:include filename="$(find h4r_rapid_robot_xacros)/def/rapid_robot.xacro"/>
	<xacro:include filename="$(find h4r_pantilt_descriptions)/def/base/base_v1.xacro"/>


	<joint name="${camera_name}/pantilt_pan_joint" type="revolute">
      <axis xyz="0 0 1"/>
      <limit lower="0" upper="${rr_const_pi}" effort="9" velocity="1" />      
      <origin xyz="0 0 0.0027" rpy="0 0 0" />
      <parent link="${camera_name}/pantilt_base_link"/>
      <child link="${camera_name}/pantilt_center_link"/>
    </joint>

    <xacro:include filename="$(find h4r_pantilt_descriptions)/def/center/center_v1.xacro"/>
		
	<joint name="${camera_name}/pantilt_tilt_joint" type="revolute">
      <axis xyz="1 0 0"/>
      <limit lower="0" upper="${rr_const_pi}" effort="9" velocity="1" />
      <origin xyz="0.0223 0 0.0455" rpy="0 0 0" />
      <parent link="${camera_name}/pantilt_center_link"/>
      <child link="${camera_name}/pantilt_head_link"/>
    </joint>
		
    <xacro:include filename="$(find h4r_pantilt_descriptions)/def/head/head_thermapp_v1.xacro"/>
    	
    	
    <xacro:include filename="$(find h4r_pantilt_descriptions)/def/gazebo/v1_gazebo.xacro"/>	

</robot>
